<?xml version="1.0" ?>
<robot name="simple_robot">
  <!-- 定义基座 -->
  <link name="base">
    <visual>
      <origin xyz="0 0 0" rpy="0 0 0" />
      <geometry>
        <box size="0.5 0.5 0.2" />
      </geometry>
      <material name="blue">
        <color rgba="0 0 1 1" />
      </material>
    </visual>
    <collision>
      <origin xyz="0 0 0" rpy="0 0 0" />
      <geometry>
        <box size="0.5 0.5 0.2" />
      </geometry>
    </collision>
    <inertial>
      <origin xyz="0 0 0" rpy="0 0 0" />
      <mass value="1.0" />
      <inertia ixx="0.01" ixy="0" ixz="0" iyy="0.01" iyz="0" izz="0.01" />
    </inertial>
  </link>

  <link name="arm0">
    <visual>
      <origin xyz="0 0 0" rpy="0 0 0" />
      <geometry>
        <cylinder radius="0.05" length="0.2" />
      </geometry>
      <material name="red">
        <color rgba="1 0 0 1" />
      </material>
    </visual>
    <collision>
      <origin xyz="0 0 0" rpy="0 0 0" />
      <geometry>
        <cylinder radius="0.05" length="0.4" />
      </geometry>
    </collision>
    <inertial>
      <origin xyz="0 0 0" rpy="0 0 0" />
      <mass value="0.5" />
      <inertia ixx="0.01" ixy="0" ixz="0" iyy="0.01" iyz="0" izz="0.01" />
    </inertial>
  </link>


  <link name="arm1">
    <visual>
      <origin xyz="0 0 0" rpy="0 0 0" />
      <geometry>
        <cylinder radius="0.05" length="0.2" />
      </geometry>
      <material name="red">
        <color rgba="1 0 0 1" />
      </material>
    </visual>
    <collision>
      <origin xyz="0 0 0" rpy="0 0 0" />
      <geometry>
         <box size="0.5 0.1 0.1" />
      </geometry>
    </collision>
    <inertial>
      <origin xyz="0 0 0" rpy="0 0 0" />
      <mass value="0.5" />
      <inertia ixx="0.01" ixy="0" ixz="0" iyy="0.01" iyz="0" izz="0.01" />
    </inertial>
  </link>

  <!-- 定义关节 -->
  <joint name="joint0" type="revolute">
    <parent link="base" />
    <child link="arm0" />
    <origin xyz="0 0 0.1" rpy="0 0 0" />
    <axis xyz="0 0 1" />
    <limit lower="-1.57" upper="1.57" effort="10.0" velocity="1.0" />
  </joint>

  <joint name="joint1" type="revolute">
    <parent link="arm0" />
    <child link="arm1" />
    <origin xyz="0 0 0.2" rpy="0 0 0" />
    <axis xyz="1 0 0" />
    <limit lower="-1.57" upper="1.57" effort="10.0" velocity="1.0" />
  </joint>

</robot>
